2025-05-09 22:33:59,801 [ERROR]: Ошибка отправки письма: (535, b'5.7.8 Error: authentication failed: This user does not have access rights to this service 1746819238-vXlvBIpLe8c0')
(<class 'smtplib.SMTPAuthenticationError'>, SMTPAuthenticationError(535, b'5.7.8 Error: authentication failed: This user does not have access rights to this service 1746819238-vXlvBIpLe8c0'), <traceback object at 0x0000020B8F4E20C0>)
Traceback (most recent call last):
  File "C:\Users\User\PycharmProjects\Blog\app.py", line 379, in register
    mail.send(msg)
  File "C:\Users\User\PycharmProjects\Blog\.venv\Lib\site-packages\flask_mail.py", line 491, in send
    with self.connect() as connection:
  File "C:\Users\User\PycharmProjects\Blog\.venv\Lib\site-packages\flask_mail.py", line 144, in __enter__
    self.host = self.configure_host()
                ^^^^^^^^^^^^^^^^^^^^^
  File "C:\Users\User\PycharmProjects\Blog\.venv\Lib\site-packages\flask_mail.py", line 165, in configure_host
    host.login(self.mail.username, self.mail.password)
  File "C:\Users\User\AppData\Local\Programs\Python\Python312\Lib\smtplib.py", line 750, in login
    raise last_exception
  File "C:\Users\User\AppData\Local\Programs\Python\Python312\Lib\smtplib.py", line 739, in login
    (code, resp) = self.auth(
                   ^^^^^^^^^^
  File "C:\Users\User\AppData\Local\Programs\Python\Python312\Lib\smtplib.py", line 662, in auth
    raise SMTPAuthenticationError(code, resp)
smtplib.SMTPAuthenticationError: (535, b'5.7.8 Error: authentication failed: This user does not have access rights to this service 1746819238-vXlvBIpLe8c0')
2025-05-09 22:39:18,668 [ERROR]: Unhandled exception: 400 Bad Request: The CSRF session token is missing. [request_id:-] [user:-] [ip:127.0.0.1]
(<class 'flask_wtf.csrf.CSRFError'>, <CSRFError '400: Bad Request'>, <traceback object at 0x000001F88279C400>)
Traceback (most recent call last):
  File "C:\Users\User\PycharmProjects\Blog\.venv\Lib\site-packages\flask_wtf\csrf.py", line 261, in protect
    validate_csrf(self._get_csrf_token())
  File "C:\Users\User\PycharmProjects\Blog\.venv\Lib\site-packages\flask_wtf\csrf.py", line 103, in validate_csrf
    raise ValidationError("The CSRF session token is missing.")
wtforms.validators.ValidationError: The CSRF session token is missing.

During handling of the above exception, another exception occurred:

Traceback (most recent call last):
  File "C:\Users\User\PycharmProjects\Blog\.venv\Lib\site-packages\flask\app.py", line 1482, in full_dispatch_request
    rv = self.preprocess_request()
         ^^^^^^^^^^^^^^^^^^^^^^^^^
  File "C:\Users\User\PycharmProjects\Blog\.venv\Lib\site-packages\flask\app.py", line 1974, in preprocess_request
    rv = self.ensure_sync(before_func)()
         ^^^^^^^^^^^^^^^^^^^^^^^^^^^^^^^
  File "C:\Users\User\PycharmProjects\Blog\.venv\Lib\site-packages\flask_wtf\csrf.py", line 229, in csrf_protect
    self.protect()
  File "C:\Users\User\PycharmProjects\Blog\.venv\Lib\site-packages\flask_wtf\csrf.py", line 264, in protect
    self._error_response(e.args[0])
  File "C:\Users\User\PycharmProjects\Blog\.venv\Lib\site-packages\flask_wtf\csrf.py", line 307, in _error_response
    raise CSRFError(reason)
flask_wtf.csrf.CSRFError: 400 Bad Request: The CSRF session token is missing.
2025-05-09 22:40:15,186 [ERROR]: Ошибка отправки письма: [WinError 10060] Попытка установить соединение была безуспешной, т.к. от другого компьютера за требуемое время не получен нужный отклик, или было разорвано уже установленное соединение из-за неверного отклика уже подключенного компьютера
(<class 'TimeoutError'>, TimeoutError(10060, 'Попытка установить соединение была безуспешной, т.к. от другого компьютера за требуемое время не получен нужный отклик, или было разорвано уже установленное соединение из-за неверного отклика уже подключенного компьютера', None, 10060, None), <traceback object at 0x000001F882842040>)
Traceback (most recent call last):
  File "C:\Users\User\PycharmProjects\Blog\app.py", line 380, in register
    mail.send(msg)
  File "C:\Users\User\PycharmProjects\Blog\.venv\Lib\site-packages\flask_mail.py", line 491, in send
    with self.connect() as connection:
  File "C:\Users\User\PycharmProjects\Blog\.venv\Lib\site-packages\flask_mail.py", line 144, in __enter__
    self.host = self.configure_host()
                ^^^^^^^^^^^^^^^^^^^^^
  File "C:\Users\User\PycharmProjects\Blog\.venv\Lib\site-packages\flask_mail.py", line 156, in configure_host
    host = smtplib.SMTP_SSL(self.mail.server, self.mail.port)
           ^^^^^^^^^^^^^^^^^^^^^^^^^^^^^^^^^^^^^^^^^^^^^^^^^^
  File "C:\Users\User\AppData\Local\Programs\Python\Python312\Lib\smtplib.py", line 1022, in __init__
    SMTP.__init__(self, host, port, local_hostname, timeout,
  File "C:\Users\User\AppData\Local\Programs\Python\Python312\Lib\smtplib.py", line 255, in __init__
    (code, msg) = self.connect(host, port)
                  ^^^^^^^^^^^^^^^^^^^^^^^^
  File "C:\Users\User\AppData\Local\Programs\Python\Python312\Lib\smtplib.py", line 341, in connect
    self.sock = self._get_socket(host, port, self.timeout)
                ^^^^^^^^^^^^^^^^^^^^^^^^^^^^^^^^^^^^^^^^^^
  File "C:\Users\User\AppData\Local\Programs\Python\Python312\Lib\smtplib.py", line 1028, in _get_socket
    new_socket = super()._get_socket(host, port, timeout)
                 ^^^^^^^^^^^^^^^^^^^^^^^^^^^^^^^^^^^^^^^^
  File "C:\Users\User\AppData\Local\Programs\Python\Python312\Lib\smtplib.py", line 312, in _get_socket
    return socket.create_connection((host, port), timeout,
           ^^^^^^^^^^^^^^^^^^^^^^^^^^^^^^^^^^^^^^^^^^^^^^^
  File "C:\Users\User\AppData\Local\Programs\Python\Python312\Lib\socket.py", line 852, in create_connection
    raise exceptions[0]
  File "C:\Users\User\AppData\Local\Programs\Python\Python312\Lib\socket.py", line 837, in create_connection
    sock.connect(sa)
TimeoutError: [WinError 10060] Попытка установить соединение была безуспешной, т.к. от другого компьютера за требуемое время не получен нужный отклик, или было разорвано уже установленное соединение из-за неверного отклика уже подключенного компьютера
2025-05-09 22:40:33,509 [ERROR]: Ошибка отправки письма: (535, b'5.7.8 Error: authentication failed: This user does not have access rights to this service 1746819632-VelaTUoLZGk0')
(<class 'smtplib.SMTPAuthenticationError'>, SMTPAuthenticationError(535, b'5.7.8 Error: authentication failed: This user does not have access rights to this service 1746819632-VelaTUoLZGk0'), <traceback object at 0x000001F882808500>)
Traceback (most recent call last):
  File "C:\Users\User\PycharmProjects\Blog\app.py", line 380, in register
    mail.send(msg)
  File "C:\Users\User\PycharmProjects\Blog\.venv\Lib\site-packages\flask_mail.py", line 491, in send
    with self.connect() as connection:
  File "C:\Users\User\PycharmProjects\Blog\.venv\Lib\site-packages\flask_mail.py", line 144, in __enter__
    self.host = self.configure_host()
                ^^^^^^^^^^^^^^^^^^^^^
  File "C:\Users\User\PycharmProjects\Blog\.venv\Lib\site-packages\flask_mail.py", line 165, in configure_host
    host.login(self.mail.username, self.mail.password)
  File "C:\Users\User\AppData\Local\Programs\Python\Python312\Lib\smtplib.py", line 750, in login
    raise last_exception
  File "C:\Users\User\AppData\Local\Programs\Python\Python312\Lib\smtplib.py", line 739, in login
    (code, resp) = self.auth(
                   ^^^^^^^^^^
  File "C:\Users\User\AppData\Local\Programs\Python\Python312\Lib\smtplib.py", line 662, in auth
    raise SMTPAuthenticationError(code, resp)
smtplib.SMTPAuthenticationError: (535, b'5.7.8 Error: authentication failed: This user does not have access rights to this service 1746819632-VelaTUoLZGk0')
2025-05-10 13:04:47,741 [ERROR]: Ошибка отправки письма: [WinError 10053] Программа на вашем хост-компьютере разорвала установленное подключение
(<class 'ConnectionAbortedError'>, ConnectionAbortedError(10053, 'Программа на вашем хост-компьютере разорвала установленное подключение', None, 10053, None), <traceback object at 0x000002B4EC282340>)
Traceback (most recent call last):
  File "C:\Users\User\PycharmProjects\Blog\app.py", line 380, in register
    mail.send(msg)
  File "C:\Users\User\PycharmProjects\Blog\.venv\Lib\site-packages\flask_mail.py", line 491, in send
    with self.connect() as connection:
  File "C:\Users\User\PycharmProjects\Blog\.venv\Lib\site-packages\flask_mail.py", line 144, in __enter__
    self.host = self.configure_host()
                ^^^^^^^^^^^^^^^^^^^^^
  File "C:\Users\User\PycharmProjects\Blog\.venv\Lib\site-packages\flask_mail.py", line 156, in configure_host
    host = smtplib.SMTP_SSL(self.mail.server, self.mail.port)
           ^^^^^^^^^^^^^^^^^^^^^^^^^^^^^^^^^^^^^^^^^^^^^^^^^^
  File "C:\Users\User\AppData\Local\Programs\Python\Python312\Lib\smtplib.py", line 1022, in __init__
    SMTP.__init__(self, host, port, local_hostname, timeout,
  File "C:\Users\User\AppData\Local\Programs\Python\Python312\Lib\smtplib.py", line 255, in __init__
    (code, msg) = self.connect(host, port)
                  ^^^^^^^^^^^^^^^^^^^^^^^^
  File "C:\Users\User\AppData\Local\Programs\Python\Python312\Lib\smtplib.py", line 341, in connect
    self.sock = self._get_socket(host, port, self.timeout)
                ^^^^^^^^^^^^^^^^^^^^^^^^^^^^^^^^^^^^^^^^^^
  File "C:\Users\User\AppData\Local\Programs\Python\Python312\Lib\smtplib.py", line 1028, in _get_socket
    new_socket = super()._get_socket(host, port, timeout)
                 ^^^^^^^^^^^^^^^^^^^^^^^^^^^^^^^^^^^^^^^^
  File "C:\Users\User\AppData\Local\Programs\Python\Python312\Lib\smtplib.py", line 312, in _get_socket
    return socket.create_connection((host, port), timeout,
           ^^^^^^^^^^^^^^^^^^^^^^^^^^^^^^^^^^^^^^^^^^^^^^^
  File "C:\Users\User\AppData\Local\Programs\Python\Python312\Lib\socket.py", line 852, in create_connection
    raise exceptions[0]
  File "C:\Users\User\AppData\Local\Programs\Python\Python312\Lib\socket.py", line 837, in create_connection
    sock.connect(sa)
ConnectionAbortedError: [WinError 10053] Программа на вашем хост-компьютере разорвала установленное подключение
2025-05-10 13:05:03,177 [ERROR]: Ошибка отправки письма: (535, b'5.7.8 Error: authentication failed: Invalid user or password! 1746871502-15dNjZ7Lda60')
(<class 'smtplib.SMTPAuthenticationError'>, SMTPAuthenticationError(535, b'5.7.8 Error: authentication failed: Invalid user or password! 1746871502-15dNjZ7Lda60'), <traceback object at 0x000002B4EC29FB80>)
Traceback (most recent call last):
  File "C:\Users\User\PycharmProjects\Blog\app.py", line 380, in register
    mail.send(msg)
  File "C:\Users\User\PycharmProjects\Blog\.venv\Lib\site-packages\flask_mail.py", line 491, in send
    with self.connect() as connection:
  File "C:\Users\User\PycharmProjects\Blog\.venv\Lib\site-packages\flask_mail.py", line 144, in __enter__
    self.host = self.configure_host()
                ^^^^^^^^^^^^^^^^^^^^^
  File "C:\Users\User\PycharmProjects\Blog\.venv\Lib\site-packages\flask_mail.py", line 165, in configure_host
    host.login(self.mail.username, self.mail.password)
  File "C:\Users\User\AppData\Local\Programs\Python\Python312\Lib\smtplib.py", line 750, in login
    raise last_exception
  File "C:\Users\User\AppData\Local\Programs\Python\Python312\Lib\smtplib.py", line 739, in login
    (code, resp) = self.auth(
                   ^^^^^^^^^^
  File "C:\Users\User\AppData\Local\Programs\Python\Python312\Lib\smtplib.py", line 662, in auth
    raise SMTPAuthenticationError(code, resp)
smtplib.SMTPAuthenticationError: (535, b'5.7.8 Error: authentication failed: Invalid user or password! 1746871502-15dNjZ7Lda60')
2025-05-10 13:06:19,416 [ERROR]: Ошибка отправки письма: (535, b'5.7.8 Error: authentication failed: Invalid user or password! 1746871579-I6dabrxLg0U0')
(<class 'smtplib.SMTPAuthenticationError'>, SMTPAuthenticationError(535, b'5.7.8 Error: authentication failed: Invalid user or password! 1746871579-I6dabrxLg0U0'), <traceback object at 0x000001B78AD75A00>)
Traceback (most recent call last):
  File "C:\Users\User\PycharmProjects\Blog\app.py", line 380, in register
    mail.send(msg)
  File "C:\Users\User\PycharmProjects\Blog\.venv\Lib\site-packages\flask_mail.py", line 491, in send
    with self.connect() as connection:
  File "C:\Users\User\PycharmProjects\Blog\.venv\Lib\site-packages\flask_mail.py", line 144, in __enter__
    self.host = self.configure_host()
                ^^^^^^^^^^^^^^^^^^^^^
  File "C:\Users\User\PycharmProjects\Blog\.venv\Lib\site-packages\flask_mail.py", line 165, in configure_host
    host.login(self.mail.username, self.mail.password)
  File "C:\Users\User\AppData\Local\Programs\Python\Python312\Lib\smtplib.py", line 750, in login
    raise last_exception
  File "C:\Users\User\AppData\Local\Programs\Python\Python312\Lib\smtplib.py", line 739, in login
    (code, resp) = self.auth(
                   ^^^^^^^^^^
  File "C:\Users\User\AppData\Local\Programs\Python\Python312\Lib\smtplib.py", line 662, in auth
    raise SMTPAuthenticationError(code, resp)
smtplib.SMTPAuthenticationError: (535, b'5.7.8 Error: authentication failed: Invalid user or password! 1746871579-I6dabrxLg0U0')
2025-05-10 13:07:09,998 [ERROR]: Ошибка отправки письма: (535, b'5.7.8 Error: authentication failed: This user does not have access rights to this service 1746871629-87dt7sxLg0U0')
(<class 'smtplib.SMTPAuthenticationError'>, SMTPAuthenticationError(535, b'5.7.8 Error: authentication failed: This user does not have access rights to this service 1746871629-87dt7sxLg0U0'), <traceback object at 0x0000020F0BB986C0>)
Traceback (most recent call last):
  File "C:\Users\User\PycharmProjects\Blog\app.py", line 380, in register
    mail.send(msg)
  File "C:\Users\User\PycharmProjects\Blog\.venv\Lib\site-packages\flask_mail.py", line 491, in send
    with self.connect() as connection:
  File "C:\Users\User\PycharmProjects\Blog\.venv\Lib\site-packages\flask_mail.py", line 144, in __enter__
    self.host = self.configure_host()
                ^^^^^^^^^^^^^^^^^^^^^
  File "C:\Users\User\PycharmProjects\Blog\.venv\Lib\site-packages\flask_mail.py", line 165, in configure_host
    host.login(self.mail.username, self.mail.password)
  File "C:\Users\User\AppData\Local\Programs\Python\Python312\Lib\smtplib.py", line 750, in login
    raise last_exception
  File "C:\Users\User\AppData\Local\Programs\Python\Python312\Lib\smtplib.py", line 739, in login
    (code, resp) = self.auth(
                   ^^^^^^^^^^
  File "C:\Users\User\AppData\Local\Programs\Python\Python312\Lib\smtplib.py", line 662, in auth
    raise SMTPAuthenticationError(code, resp)
smtplib.SMTPAuthenticationError: (535, b'5.7.8 Error: authentication failed: This user does not have access rights to this service 1746871629-87dt7sxLg0U0')
2025-05-10 13:15:42,989 [ERROR]: Ошибка отправки письма: (535, b'5.7.8 Username and Password not accepted. For more information, go to\n5.7.8  https://support.google.com/mail/?p=BadCredentials 2adb3069b0e04-54fc64bfc92sm604146e87.200 - gsmtp')
(<class 'smtplib.SMTPAuthenticationError'>, SMTPAuthenticationError(535, b'5.7.8 Username and Password not accepted. For more information, go to\n5.7.8  https://support.google.com/mail/?p=BadCredentials 2adb3069b0e04-54fc64bfc92sm604146e87.200 - gsmtp'), <traceback object at 0x0000024874B3DA00>)
Traceback (most recent call last):
  File "C:\Users\User\PycharmProjects\Blog\app.py", line 379, in register
    mail.send(msg)
  File "C:\Users\User\PycharmProjects\Blog\.venv\Lib\site-packages\flask_mail.py", line 491, in send
    with self.connect() as connection:
  File "C:\Users\User\PycharmProjects\Blog\.venv\Lib\site-packages\flask_mail.py", line 144, in __enter__
    self.host = self.configure_host()
                ^^^^^^^^^^^^^^^^^^^^^
  File "C:\Users\User\PycharmProjects\Blog\.venv\Lib\site-packages\flask_mail.py", line 165, in configure_host
    host.login(self.mail.username, self.mail.password)
  File "C:\Users\User\AppData\Local\Programs\Python\Python312\Lib\smtplib.py", line 750, in login
    raise last_exception
  File "C:\Users\User\AppData\Local\Programs\Python\Python312\Lib\smtplib.py", line 739, in login
    (code, resp) = self.auth(
                   ^^^^^^^^^^
  File "C:\Users\User\AppData\Local\Programs\Python\Python312\Lib\smtplib.py", line 662, in auth
    raise SMTPAuthenticationError(code, resp)
smtplib.SMTPAuthenticationError: (535, b'5.7.8 Username and Password not accepted. For more information, go to\n5.7.8  https://support.google.com/mail/?p=BadCredentials 2adb3069b0e04-54fc64bfc92sm604146e87.200 - gsmtp')
2025-05-10 13:17:04,636 [ERROR]: Unhandled exception: 400 Bad Request: The CSRF session token is missing. [request_id:-] [user:-] [ip:127.0.0.1]
(<class 'flask_wtf.csrf.CSRFError'>, <CSRFError '400: Bad Request'>, <traceback object at 0x000001CF97EFA380>)
Traceback (most recent call last):
  File "C:\Users\User\PycharmProjects\Blog\.venv\Lib\site-packages\flask_wtf\csrf.py", line 261, in protect
    validate_csrf(self._get_csrf_token())
  File "C:\Users\User\PycharmProjects\Blog\.venv\Lib\site-packages\flask_wtf\csrf.py", line 103, in validate_csrf
    raise ValidationError("The CSRF session token is missing.")
wtforms.validators.ValidationError: The CSRF session token is missing.

During handling of the above exception, another exception occurred:

Traceback (most recent call last):
  File "C:\Users\User\PycharmProjects\Blog\.venv\Lib\site-packages\flask\app.py", line 1482, in full_dispatch_request
    rv = self.preprocess_request()
         ^^^^^^^^^^^^^^^^^^^^^^^^^
  File "C:\Users\User\PycharmProjects\Blog\.venv\Lib\site-packages\flask\app.py", line 1974, in preprocess_request
    rv = self.ensure_sync(before_func)()
         ^^^^^^^^^^^^^^^^^^^^^^^^^^^^^^^
  File "C:\Users\User\PycharmProjects\Blog\.venv\Lib\site-packages\flask_wtf\csrf.py", line 229, in csrf_protect
    self.protect()
  File "C:\Users\User\PycharmProjects\Blog\.venv\Lib\site-packages\flask_wtf\csrf.py", line 264, in protect
    self._error_response(e.args[0])
  File "C:\Users\User\PycharmProjects\Blog\.venv\Lib\site-packages\flask_wtf\csrf.py", line 307, in _error_response
    raise CSRFError(reason)
flask_wtf.csrf.CSRFError: 400 Bad Request: The CSRF session token is missing.
2025-05-10 13:17:32,512 [ERROR]: Ошибка отправки письма: (535, b'5.7.8 Username and Password not accepted. For more information, go to\n5.7.8  https://support.google.com/mail/?p=BadCredentials 38308e7fff4ca-326c33b7dd4sm5383261fa.43 - gsmtp')
(<class 'smtplib.SMTPAuthenticationError'>, SMTPAuthenticationError(535, b'5.7.8 Username and Password not accepted. For more information, go to\n5.7.8  https://support.google.com/mail/?p=BadCredentials 38308e7fff4ca-326c33b7dd4sm5383261fa.43 - gsmtp'), <traceback object at 0x000001CF97FB97C0>)
Traceback (most recent call last):
  File "C:\Users\User\PycharmProjects\Blog\app.py", line 379, in register
    mail.send(msg)
  File "C:\Users\User\PycharmProjects\Blog\.venv\Lib\site-packages\flask_mail.py", line 491, in send
    with self.connect() as connection:
  File "C:\Users\User\PycharmProjects\Blog\.venv\Lib\site-packages\flask_mail.py", line 144, in __enter__
    self.host = self.configure_host()
                ^^^^^^^^^^^^^^^^^^^^^
  File "C:\Users\User\PycharmProjects\Blog\.venv\Lib\site-packages\flask_mail.py", line 165, in configure_host
    host.login(self.mail.username, self.mail.password)
  File "C:\Users\User\AppData\Local\Programs\Python\Python312\Lib\smtplib.py", line 750, in login
    raise last_exception
  File "C:\Users\User\AppData\Local\Programs\Python\Python312\Lib\smtplib.py", line 739, in login
    (code, resp) = self.auth(
                   ^^^^^^^^^^
  File "C:\Users\User\AppData\Local\Programs\Python\Python312\Lib\smtplib.py", line 662, in auth
    raise SMTPAuthenticationError(code, resp)
smtplib.SMTPAuthenticationError: (535, b'5.7.8 Username and Password not accepted. For more information, go to\n5.7.8  https://support.google.com/mail/?p=BadCredentials 38308e7fff4ca-326c33b7dd4sm5383261fa.43 - gsmtp')
2025-05-10 13:18:38,084 [ERROR]: Ошибка отправки письма: (535, b'5.7.8 Error: authentication failed: This user does not have access rights to this service 1746872317-aIdqbHxLda60')
(<class 'smtplib.SMTPAuthenticationError'>, SMTPAuthenticationError(535, b'5.7.8 Error: authentication failed: This user does not have access rights to this service 1746872317-aIdqbHxLda60'), <traceback object at 0x000002EDDAFA28C0>)
Traceback (most recent call last):
  File "C:\Users\User\PycharmProjects\Blog\app.py", line 380, in register
    mail.send(msg)
  File "C:\Users\User\PycharmProjects\Blog\.venv\Lib\site-packages\flask_mail.py", line 491, in send
    with self.connect() as connection:
  File "C:\Users\User\PycharmProjects\Blog\.venv\Lib\site-packages\flask_mail.py", line 144, in __enter__
    self.host = self.configure_host()
                ^^^^^^^^^^^^^^^^^^^^^
  File "C:\Users\User\PycharmProjects\Blog\.venv\Lib\site-packages\flask_mail.py", line 165, in configure_host
    host.login(self.mail.username, self.mail.password)
  File "C:\Users\User\AppData\Local\Programs\Python\Python312\Lib\smtplib.py", line 750, in login
    raise last_exception
  File "C:\Users\User\AppData\Local\Programs\Python\Python312\Lib\smtplib.py", line 739, in login
    (code, resp) = self.auth(
                   ^^^^^^^^^^
  File "C:\Users\User\AppData\Local\Programs\Python\Python312\Lib\smtplib.py", line 662, in auth
    raise SMTPAuthenticationError(code, resp)
smtplib.SMTPAuthenticationError: (535, b'5.7.8 Error: authentication failed: This user does not have access rights to this service 1746872317-aIdqbHxLda60')
